Workbook

Sheet Data and Count
A1: Program Count by Year
A13: COUNTA of Duplicate Record
A14: COUNTA of Duplicate Record | B14: Year
A15: Duplicate Record | C15: 20 - 21 | D15: 21 - 22 | E15: 21 - 22, 20 - 21 | F15: 22 - 23 | G15: 23 - 24 | H15: Grand Total
A16: Duplicate | B16: 19 | C16: 11 | D16: 40 | E16: 1 | F16: 72 | G16: 8 | H16: 151
A17: Grand Total | B17: 19 | C17: 11 | D17: 40 | E17: 1 | F17: 72 | G17: 8 | H17: 151
A19: School Count

Sheet #Cheers4Careers Info Update For
A1: Timestamp | B1: Email Address | C1: Full Name | D1: Full Address with Zip Code (this will help us identify opportunities for you) | E1: Phone Number | F1: What is your current career interest? | G1: What school do you attend? (If you're not in school, put N/A) | H1: Do you have a job? If so, what company are you with and what do you do? (If you are not currently employed, put N/A) | I1: Are you looking for an internship or job? Tell us more. | J1: What #Cheers4Careers event are you attending? (Provide the date and location) | K1: Would you like to participate in the following (please select all that you're interested in) | L1: Please let us know if you have any food allergies or food restrictions
A2: 46105.769 | B2: ousmane@speakhire.org | C2: Ousmane Diallo | D2: 1011 East 53rd street Brooklyn NY 11234 | E2: 6467038461 | F2: Tech ( Mainframe) | G2: CUNY City Tech | H2: N/A | I2: Yes. | J2: March 24 Midtown | K2: SpeakHire Summit - June 7 - Connect with other alumni for a day of professional development and networking
A3: 46105.896 | B3: jhanmottap@gmail.com | C3: Jhan pier Motta Londoño | D3: 3540 83rd Jackson heights 11372 | E3: 6467256084 | F3: Theater ( acting ) and art ( photography) | G3: Brooklyn College | H3: Freelance model | I3: If there is an job opportunity that is relate with art. | J3: 03/24/26 (246 W 38th St) | K3: Other #Cheers4Careers events -- Alumni #Cheers4Careers is March 28th from 1 - 3 pm at Queens Museum featuring 3 Champions speaking about leadership
A4: 46106.369 | B4: naim.bakere@ellisprep.com | C4: Naim Bakere | D4: 2015 Southern Blvd 9c Bronx NY 10460 | E4: 9294221124 | F4: Business administration | G4: Monroe University expre | H4: I work with kid from KidFit soccer. We usually have different locations, so we work depending on the schedule. There is part time and full time.Since I’m a college student athlete,I work part time there. The kid are wonderful, good learners we enjoy every moment. I also do other shift as security certain day | I4: Not right now, but it would be for my colleague who is in college right now also. | J4: March 24 Midtown | K4: SpeakHire Summit - June 7 - Connect with other alumni for a day of professional development and networking
A5: 46106.897 | B5: mi577957@gmail.com | C5: Mingyu(Carl) Huo | D5: 14620 58th Ave, Flushing NY 11355 | E5: 929-319-9980 | F5: Math Education | G5: Queens College | H5: N/A | I5: Looking for jobs in education field | J5: March 28th Queens Museum | K5: Other #Cheers4Careers events -- Alumni #Cheers4Careers is March 28th from 1 - 3 pm at Queens Museum featuring 3 Champions speaking about leadership
A6: 46108.496 | B6: ousmane@speakhire.org | C6: Ousmane Diallo | D6: 1011 East 53rd street Brooklyn NY 11234 | E6: 6467038461 | F6: Systems programming | G6: City Tech | H6: N/A | I6: Both | J6: Cheers4Careers Alumni | K6: SpeakHire Summit - June 7 - Connect with other alumni for a day of professional development and networking, Other #Cheers4Careers events -- Alumni #Cheers4Careers is March 28th from 1 - 3 pm at Queens Museum featuring 3 Champions speaking about leadership
A7: 46108.945 | B7: jackelinemoran278@gmail.com | C7: Jackeline Susano Moran | D7: 104-41 41st Ave Corona NY 11368 | E7: 9179436216 | F7: Medical/Research | G7: Talent Unlimited High School | H7: N/A | I7: Yes, part time maybe | J7: Alumni- 03/28/26 @Queens Museum | K7: #SpeakingMyName - June 16th - Share your name story video and join the campaign!, SpeakHire Summit - June 7 - Connect with other alumni for a day of professional development and networking, Other #Cheers4Careers events -- Alumni #Cheers4Careers is March 28th from 1 - 3 pm at Queens Museum featuring 3 Champions speaking about leadership
A8: 46109.388 | B8: elisaoch3@gmail.com | C8: Elisa och | D8: 142-19 horace harding express way 11367 | E8: 9496878921 | F8: Airforce | G8: john bowne high school | H8: No i do not have a job | I8: Yes i am looking for a job | J8: Queens museum 3/28/2026 | K8: Other #Cheers4Careers events -- Alumni #Cheers4Careers is March 28th from 1 - 3 pm at Queens Museum featuring 3 Champions speaking about leadership
A9: 46109.411 | B9: mahaic2023@gmail.com | C9: Mahia | D9: 10453 | E9: 92296705851 | F9: Yes | G9: ! | H9: N | I9: Yes | J9: Yes | K9: #SpeakingMyName - June 16th - Share your name story video and join the campaign!, SpeakHire Summit - June 7 - Connect with other alumni for a day of professional development and networking, Other #Cheers4Careers events -- Alumni #Cheers4Careers is March 28th from 1 - 3 pm at Queens Museum featuring 3 Champions speaking about leadership
A10: 46109.441 | B10: mennatallah@speakhire.org | C10: Mennatallah Mahmoud | D10: 490 Grandview Ave, Ridgewood, NY 11385 | E10: 9293314859 | F10: Law | G10: MESA Charter High School | H10: N/A | I10: Yes, I would like to find a virtual internship, so it doesn’t effect school. | J10: 3/28/2026 Queens Museum | K10: #SpeakingMyName - June 16th - Share your name story video and join the campaign!, SpeakHire Summit - June 7 - Connect with other alumni for a day of professional development and networking, Other #Cheers4Careers events -- Alumni #Cheers4Careers is March 28th from 1 - 3 pm at Queens Museum featuring 3 Champions speaking about leadership
A11: 46109.447 | B11: leyli@speakhire.org | C11: Leyli Hernandez | D11: 99-22 42nd Ave Bsmt Corona NY 11368 | E11: (347)453-8142 | F11: STEM, Agriculture, Environmental | G11: Academy of American Studies | H11: N/A | I11: Yes, I am looking for a job for during the summer because at the moment I am busy with school and after school practices. | J11: 03/28/2026 at the Queens Museum | K11: SpeakHire Summit - June 7 - Connect with other alumni for a day of professional development and networking, Other #Cheers4Careers events -- Alumni #Cheers4Careers is March 28th from 1 - 3 pm at Queens Museum featuring 3 Champions speaking about leadership
A12: 46111.538 | B12: samueltavarez74@gmail.com | C12: Samuel Tavarez | D12: 559 W 158 St 10032 New York, NY | E12: 6463387513 | F12: Finance, International Business | G12: Baruch College | H12: N/A | I12: Intership | J12: April 18 Queens Museum | K12: SpeakHire Summit - June 7 - Connect with other alumni for a day of professional development and networking
A13: 46116.072 | B13: Cristinape31@gmail.com | C13: Jayda Caimares | D13: 65-21 79th st Middle Village NY 11379 | E13: 646-421-9589 | F13: Student | G13: PS 49 Middle Village NY 11379 | H13: Student | I13: Student | J13: Saturday, April 18 Queens Museum | K13: #SpeakingMyName - June 16th - Share your name story video and join the campaign!, SpeakHire Summit - June 7 - Connect with other alumni for a day of professional development and networking | L13: N/A
A14: 46116.074 | B14: Cristinape31@gmail.com | C14: Cristina Peña Caimares | D14: 65-21 79th st Middle Village NY 11379 | E14: 646-421-9589 | F14: Student | G14: Student | H14: Department of Education | I14: Speech Pathology | J14: Saturday, April 18 Queens Museum | K14: #SpeakingMyName - June 16th - Share your name story video and join the campaign!, SpeakHire Summit - June 7 - Connect with other alumni for a day of professional development and networking | L14: N/A
A15: 46122.654 | B15: elisaoch3@gmail.com | C15: Elisa och | D15: 142-19 horace harding expressway 11367 | E15: 9496878921 | F15: Health and nutrition science | G15: John Bowne highschool | H15: no i do not have a job | I15: no i am not intrested in any jobs yet maybe after highschool yeah | J15: Saturday april 18th 2026 | K15: #SpeakingMyName - June 16th - Share your name story video and join the campaign!, SpeakHire Summit - June 7 - Connect with other alumni for a day of professional development and networking, Other #Cheers4Careers events -- Alumni #Cheers4Careers is March 28th from 1 - 3 pm at Queens Museum featuring 3 Champions speaking about leadership | L15: No i do not have any allergies
A16: 46122.763 | B16: richie334455@gmail.com | C16: Richie Hung | D16: 108-19 71 AVENUE FOREST HILLS, NY 11375 | E16: 6466175246 | F16: Economic and data science | G16: Baruch college | H16: Retail | I16: I am looking for internships related to my major | J16: April 18th, forest hill public library | K16: SpeakHire Summit - June 7 - Connect with other alumni for a day of professional development and networking | L16: N/A
A17: 46123.872 | B17: raselali833@gmail.com | C17: Rasel Ali | D17: 10472 | E17: 9293305644 | F17: Education, non profit org, operations management | G17: CUNY Lehman | H17: Substitute NYC DOE | I17: . | J17: April 18, both ice cream and leadership talk | K17: #SpeakingMyName - June 16th - Share your name story video and join the campaign! | L17: N/A
A18: 46124.463 | B18: ousmane@speakhire.org | C18: Ousmane Diallo | D18: 11234 | E18: 6467038461 | F18: Research Scientists | G18: City Tech | H18: N/A | I18: Yes | J18: April 18 | K18: SpeakHire Summit - June 7 - Connect with other alumni for a day of professional development and networking | L18: Shrimp
A19: 46125.969 | B19: leyli@speakhire.org | C19: Leyli Hernandez | D19: 99-22 42nd Ave Bsmt Corona NY 11368 | E19: (347)453-8142 | F19: STEM, Agricultural Engineering, | G19: Academy of American Studies | H19: N/A | I19: I am currently working in my resume and have some companies in mind to apply at, but a internship would also help me with my career development so I may look into that as well. | J19: April 18 at Cookies n’ Cream 70-17 Austin St Forest Hills NY 11375 | K19: SpeakHire Summit - June 7 - Connect with other alumni for a day of professional development and networking, Other #Cheers4Careers events -- Alumni #Cheers4Careers is March 28th from 1 - 3 pm at Queens Museum featuring 3 Champions speaking about leadership | L19: No allergies or food restrictions
A20: 46128.709 | B20: yiengchukdorji123@gmail.com | C20: Yeingchuk Dorji | D20: 11373 | E20: 6462095546 | F20: Law, psychology | G20: Arizona state university | H20: Babysitting job | I20: Yes, currently looking for internships | J20: April 18 | K20: Other #Cheers4Careers events -- Alumni #Cheers4Careers is March 28th from 1 - 3 pm at Queens Museum featuring 3 Champions speaking about leadership | L20: I can help out with the set up.
A21: 46130.436 | B21: akiramartinez002@gmail.com | C21: Akira Z. Quezada | D21: 124 Farnham avenue, Garfield, NJ 07026. | E21: 7188442579 | F21: Biomedical engineering. | G21: The City College of New York. | H21: I work at International Community High School, I am a math tuttor. | I21: Yes, I'm looking for an internship in the STEM field, or a part time job related to my career interest. | J21: Ice cream and networking, leadership talks. | K21: SpeakHire Summit - June 7 - Connect with other alumni for a day of professional development and networking | L21: No allergies.
A22: 46140.769 | B22: ousmane@speakhire.org | C22: Ousmane Diallo | D22: 11234 | E22: 6467038461 | F22: Research Scientist in AI/ML | G22: CUNY City Tech | H22: N/A | I22: Yes | J22: May 24 | K22: #SpeakingMyName - June 16th - Share your name story video and join the campaign!, SpeakHire Summit - June 7 - Connect with other alumni for a day of professional development and networking, Other #Cheers4Careers events -- Alumni #Cheers4Careers is March 28th from 1 - 3 pm at Queens Museum featuring 3 Champions speaking about leadership | L22: No seafood
A23: 46154.545 | B23: ousmane@speakhire.org | C23: Ousmane Diallo | D23: 11234 | E23: 6467038461 | F23: Research in AI | G23: CUNY City Tech | H23: No | I23: Yes | J23: May 24 Lehman College | K23: #SpeakingMyName - June 16th - Share your name story video and join the campaign!, SpeakHire Summit - June 7 - Connect with other alumni for a day of professional development and networking, Other #Cheers4Careers events -- Alumni #Cheers4Careers is March 28th from 1 - 3 pm at Queens Museum featuring 3 Champions speaking about leadership | L23: No seafood
A24: 46159.686 | B24: libanezadelacruz4@gmail.com | C24: Jhanna De La Cruz | D24: 156E 171st St 3L Bronx, NY 10452 | E24: 9294044915 | F24: Social worker, Assistant Research, Human Resources and career related to psychology . | G24: N/A | H24: N/A | I24: Job but can be both. | J24: Lehman college Bronx, May 24 | K24: SpeakHire Summit - June 7 - Connect with other alumni for a day of professional development and networking | L24: No
A25: 46161.476 | B25: naimbakere@ellisprep.com | C25: Naim | D25: 2015 southern blvd 9c Bronx NY 10460 | E25: 9 | F25: Data analysis | G25: Monroe graduated | H25: PPI security duty | I25: Yes flexible job and good location | J25: Lehman college Bronx | K25: SpeakHire Summit - June 11 - Connect with other alumni for a day of professional development and networking, Other #Cheers4Careers events -- Alumni #Cheers4Careers is May 24th from 1 - 3 pm at Lehman College | L25: N/A

Sheet Champions
A1: First Name | B1: Last Name | C1: Full Name | D1: Phone Number | E1: Email Address | F1: Contact Status | G1: Kintone Record Number | H1: Hub Champion ID | I1: Hub User ID | J1: Main Career Field | K1: Notes | L1: Date Applied | M1: NY Congressional Districts | N1: NY Senate District | O1: NY Assembly District | P1: NYC City Council District | Q1: Address | R1: Current Location | S1: City | T1: State | U1: Current Company | V1: Programs Participated in | W1: Connected Interns | X1: Partner Orgs Supported | Y1: Testimonials | Z1: #Cheers4Careers Outreach | AA1: Soiree Outreach | AB1: Hub Active | AC1: Unsubscribed from Mailing List | AD1: Magazine Issue Mailed | AE1: Magazine Issue Mailed Date | AF1: Purpose of mailing | AG1: Donation Amount
A2: Tahsina | B2: Ahmed | C2: =CONCATENATE(A2," ",B2) -> Tahsina Ahmed | F2: Inactive CPC | G2: 671 | H2: {=IFERROR(INDEX('Hub CPC 226'!A:A, MATCH(C2, 'Hub CPC 226'!B:B, 0)), "")} -> 5 | I2: {=IFERROR(INDEX('Hub Users 226'!A:A, MATCH(C2, 'Hub Users 226'!B:B, 0)), "")} -> 25 | J2: STEM (Science, Technology, Engineering, Math) | L2: 44851.765 | T2: NJ | V2: FY 17 - 18 | W2: Ecstacy Holland and Mimi Agbobli | X2: American History | AB2: =IFERROR(__xludf.DUMMYFUNCTION("IF( ISNUMBER(MATCH( C2, IMPORTRANGE(""https://docs.google.com/spreadsheets/d/1yTh1ELC33JHYOeEdgIiEclxPRyh0zOKtlawDltfUay8"",""'Champions'!A:A""), 0 )), ""Outreach Conducted"", """")"),"")
A3: John ?Nico? | B3: Johnson | C3: =CONCATENATE(A3," ",B3) -> John ?Nico? Johnson | D3: 8582600744 | E3: 1nicojohnson@gmail.com | F3: Active CPC | G3: 399 | H3: {=IFERROR(INDEX('Hub CPC 226'!A:A, MATCH(C3, 'Hub CPC 226'!B:B, 0)), "")} -> 6 | I3: {=IFERROR(INDEX('Hub Users 226'!A:A, MATCH(C3, 'Hub Users 226'!B:B, 0)), "")} -> 26 | K3: 1/11/23 SB sent email about IR2 12/19/22 Nico confirmed Wheels schedule for IR2. CT 12/08/22 CT asked about Wheels schedule for IR2 12/16/21 Nico has only shown to 1 out of 4 sessions for FY21-22 IR1 so far SB Nico is active US Navy for the past 13 years Can be matched on Engineering and law enforcement / army Nico has basic Spanish (can understand at a minimum really) and told Hetal to take it off as a language. Can match on Spanish if the student puts 'Somewhat Comfortable' put shows higher proficiency and needs someone without the Spanish cruth. He can do Japanese (conversational) and ASL. (HJ, 10/20/21) Nico informed us on May 3rd, 2021 that he changed companies from Insight Global to Bravura (HJ) Nico attended a training on 2/26/21 with JPS JPS followed up on 2/20/21 &#43; invited Nico to schedule a training Nico was screened on 2/19/21 by Malak Baker at 1 pm est Double checked 1/26 (KW) | L3: 44200.699 | Q3: 630 8th Avenue, San Diego | R3: San Diego | S3: San Diego | T3: CA | U3: Bravura | V3: Seminars 22, Seminars 21, FY 22 - 23, FY 21 - 22, FY 20 - 21 | W3: Richard Murillo, Aristid Reynoso, Emanuel Ortiz, Jason Hernandez, Rubaya Nasrin, Michael Suarez Suarez, Vimadel Estrella, Alessandro Pineda, Elver Veras, Maria Ventura, Francis Calderon, Jose Rivera and Trisha Landolt | X3: ClaremontIHS, WheelsNYC, HSEI, IHS Health, FlushingIHS | AB3: =IFERROR(__xludf.DUMMYFUNCTION("IF( ISNUMBER(MATCH( C3, IMPORTRANGE(""https://docs.google.com/spreadsheets/d/1yTh1ELC33JHYOeEdgIiEclxPRyh0zOKtlawDltfUay8"",""'Champions'!A:A""), 0 )), ""Outreach Conducted"", """")"),"")
A4: Abdelrahman | B4: Bannora | C4: =CONCATENATE(A4," ",B4) -> Abdelrahman Bannora | D4: 201200000000 | E4: a_bannora@yahoo.co.uk | F4: Inactive CPC | G4: 491 | H4: {=IFERROR(INDEX('Hub CPC 226'!A:A, MATCH(C4, 'Hub CPC 226'!B:B, 0)), "")} -> 7 | I4: {=IFERROR(INDEX('Hub Users 226'!A:A, MATCH(C4, 'Hub Users 226'!B:B, 0)), "")} -> 27 | J4: Health Sciences/Medicine | K4: Has no US experience so asked to be a seminar speaker or Speaker Series speaker (SB, 9/21/21) Screening call completed 9/2/21 SB Sent screening scheduling email 8/23/21 SB | L4: 44427.463 | Q4: Building 12A,Street 42, 11th district, Zayed, Giza, Egypt | R4: Cairo, Egypt | U4: N/A, I'm a freelancer | AB4: =IFERROR(__xludf.DUMMYFUNCTION("IF( ISNUMBER(MATCH( C4, IMPORTRANGE(""https://docs.google.com/spreadsheets/d/1yTh1ELC33JHYOeEdgIiEclxPRyh0zOKtlawDltfUay8"",""'Champions'!A:A""), 0 )), ""Outreach Conducted"", """")"),"")
A5: Andres | B5: Rubiano | C5: =CONCATENATE(A5," ",B5) -> Andres Rubiano | D5: (941) 296-5946 | E5: Aar2213@tc.Columbia.edu | F5: Active CPC | G5: 647 | H5: {=IFERROR(INDEX('Hub CPC 226'!A:A, MATCH(C5, 'Hub CPC 226'!B:B, 0)), "")} | I5: {=IFERROR(INDEX('Hub Users 226'!A:A, MATCH(C5, 'Hub Users 226'!B:B, 0)), "")} -> 28 | J5: Entertainment/Lifestyle | K5: 3/31/23 CT updated bio &amp; job title 3/23/23 CT updated email to Aar2213@tc.Columbia.edu 3/15/23 CT asked to be in-person Seminar Speaker at BUSHWICKCHS | L5: 44678.582 | R5: New York | T5: NY | U5: SuitUp | V5: Seminars 23, Seminars 22 | X5: BUSHWICKCHS, P2GBronx | AB5: =IFERROR(__xludf.DUMMYFUNCTION("IF( ISNUMBER(MATCH( C5, IMPORTRANGE(""https://docs.google.com/spreadsheets/d/1yTh1ELC33JHYOeEdgIiEclxPRyh0zOKtlawDltfUay8"",""'Champions'!A:A""), 0 )), ""Outreach Conducted"", """")"),"")
A6: Abhishek | B6: Mehta | C6: =CONCATENATE(A6," ",B6) -> Abhishek Mehta | D6: 16692884132 | E6: abhisshekmehta@gmail.com | F6: Active CPC | G6: 489 | H6: {=IFERROR(INDEX('Hub CPC 226'!A:A, MATCH(C6, 'Hub CPC 226'!B:B, 0)), "")} -> 9 | I6: {=IFERROR(INDEX('Hub Users 226'!A:A, MATCH(C6, 'Hub Users 226'!B:B, 0)), "")} -> 29 | J6: Health Sciences/Medicine | K6: 7/17/23 - SB sent email for IRS, BC called &amp; left VM, SB sent follow up text 1/12/23 emailed SB, &#34;My schedule will not allow me to undertake this project over the next several months. As much as I loved doing this, I'll have to skip for the next few months at least.&#34; - not available for IR2 and IR3 - try for FY 23-24 IRS or IR1 1/11/23 SB sent email for IR2 for Mondays 3/6/22 Emailed in response to IR3 availability request saying he is not available for this round but is interested in future rounds Completed Training and Onboarding on 9/1/21 SB Training scheduling email sent 8/10/21 Passed screening 8/9/21 SB Sent follow up scheduling email 8/4/21 SB Sent screening scheduling email 8/2/21 SB Social Media Handle: @abhisshekmehta | L6: 44410.79 | Q6: 1836 Lee Way, Milpitas, CA 95035 | R6: Milpitas, CA | S6: Milpitas | T6: CA | U6: Tesla, Inc. | V6: FY 21 - 22 | W6: Ousmane Diallo, Abdelrahman Mohamed, Ricaldyne Saturne, Ligia Espinoza, Eliana Alfonso Hernandez and Paola Munoz | X6: NYC Mission - Emma Lazarus, IHS Lafayette, IHS Health, FlushingIHS | AB6: =IFERROR(__xludf.DUMMYFUNCTION("IF( ISNUMBER(MATCH( C6, IMPORTRANGE(""https://docs.google.com/spreadsheets/d/1yTh1ELC33JHYOeEdgIiEclxPRyh0zOKtlawDltfUay8"",""'Champions'!A:A""), 0 )), ""Outreach Conducted"", """")"),"")
A7: Adela | B7: Cimic | C7: =CONCATENATE(A7," ",B7) -> Adela Cimic | D7: 6365412393 | E7: adelacimic@gmail.com | F7: Active CPC | G7: 416 | H7: {=IFERROR(INDEX('Hub CPC 226'!A:A, MATCH(C7, 'Hub CPC 226'!B:B, 0)), "")} -> 10 | I7: {=IFERROR(INDEX('Hub Users 226'!A:A, MATCH(C7, 'Hub Users 226'!B:B, 0)), "")} -> 30 | J7: Business | K7: Not available for IR1 &amp; probably not much time in the future due to personal reasons. CT 9/7/22 7/5/22 LG reached out for IRS availability 3/24/22 Not available for Seminars in May &amp; June due to visiting family overseas. CT 3/21/22 Not available for IR3 CT 12/22/21 SB sent IR2 FY21-22 schedule list for matching Adela attended a training webinar on 3/8/21 with JPS HJ marked Adela as Active Green based off of Malak's notes from screening (2/26/2021) Adela had a screening call with Malak Baker on 2/15/21 JPS emailed on 2/7/2021 to schedule a Screening Call Double checked 1/26 (KW) | L7: 44200.819 | M7: 7 | N7: 59 | O7: 50 | P7: 33 | Q7: 208 Java St apt 1A, Brooklyn NY | R7: NYC | S7: Brooklyn | T7: NY | U7: Columbia university medical center | V7: Seminars 22, FY 20 - 21 | W7: Dariel Harrison and Blair Vales | X7: IHSUnionSquare, QueensPrepAcad | AB7: =IFERROR(__xludf.DUMMYFUNCTION("IF( ISNUMBER(MATCH( C7, IMPORTRANGE(""https://docs.google.com/spreadsheets/d/1yTh1ELC33JHYOeEdgIiEclxPRyh0zOKtlawDltfUay8"",""'Champions'!A:A""), 0 )), ""Outreach Conducted"", """")"),"")
A8: Addy Michelle | B8: Jimenez Haga | C8: =CONCATENATE(A8," ",B8) -> Addy Michelle Jimenez Haga | D8: 17142903471 | E8: adrianna.haga@gmail.com | F8: Active CPC | G8: 55 | H8: {=IFERROR(INDEX('Hub CPC 226'!A:A, MATCH(C8, 'Hub CPC 226'!B:B, 0)), "")} -> 11 | I8: {=IFERROR(INDEX('Hub Users 226'!A:A, MATCH(C8, 'Hub Users 226'!B:B, 0)), "")} -> 31 | J8: Armed Services/Law Enforcement | K8: 12/4/23 Addy confirmed availability for IR2, SB emailed About Interns to confirm group 11/29/23 Add replied to newsletter saying she was interested in IR2 - SB sent dates to check availability Addy made the #ChampionItForward video 7/18/23 WW emailed for IRS availability, FG followed up with call and text, not available for IRS - &#34;If something comes up between 11:30 - 1:00 PM PDT please let me know.&#34; 12/16/22 Addy confirmed availability for IR2 - Mondays at 3 pm est 12/13/22 SB sent follow up email about matching - Addy responded that she is talking with boss and will get back to us later this week 12/6/22 SB emailed schedules and request for IR2 12/1/22 emailed SB current availability: 6-7 am or between 11:00 - 1:00 pm PST (9-10 am est or 2-4 pm est) Travelling most of November and might not be able to join IR1. She wants to receive schedule though and might be able to participate. Best times for her are 11 am to 1:30 pm PST. CT 08/31/2022 7/12/22 Addy emailed letting us know availability/flexibility at work is limited. Doing internship rounds early in the morning (pst) would work better for her. SB 3/14/22 Not available for IR3 due to new position at work. Reach out for next round. CT Best form of contact is phone 2/18/22 SB asked Addy for a seminar, she would love to but unable to Monday thru Thursday when also doing sessions. Asked to be considered for Friday Seminars! She waited over a year for a mentee and wasn't match due to lack of school partners at the time. She said she is no longer available but if you have a good match, it might be worth reaching out to see. | L8: 43338.743 | Q8: 1723 Capitol Ave Apt 6, Sacramento, CA 95811 | S8: Sacramento | T8: CA | U8: California Governor's Office of Emergency Services (Cal OES) | V8: Seminars 21, FY 20 - 21, FY 21 - 22, FY 22 - 23, FY 23 - 24 | W8: Licsy Reyes, Tariana Garcia Encarnacion, Tasnim Jahan, Bianka Pena, Rafialy Carrasco, Ofelia (Sara) Lopez, Emili Ordonez, Jazling Garcia Garcia, Wilberto Verlasquez, Norvia Tavarez, Robeliza Nunez, Daniela Gonzalez, Claudia Herazo, Karilyne Suazo, Tariana Garcia Encarnacion, Ronald Pujols, Lesly Chucino, Lia Luciano, Yoleinny Sosa Marte and Lleilin Guerra | X8: SOF, ELLIS, CrotonaIHS | AB8: =IFERROR(__xludf.DUMMYFUNCTION("IF( ISNUMBER(MATCH( C8, IMPORTRANGE(""https://docs.google.com/spreadsheets/d/1yTh1ELC33JHYOeEdgIiEclxPRyh0zOKtlawDltfUay8"",""'Champions'!A:A""), 0 )), ""Outreach Conducted"", """")"),"")
A9: Ashley Elizabeth | B9: Hudson-Hines | C9: =CONCATENATE(A9," ",B9) -> Ashley Elizabeth Hudson-Hines | D9: 619-243-4904 | E9: aehhines@gmail.com | F9: Active CPC | G9: 110 | H9: {=IFERROR(INDEX('Hub CPC 226'!A:A, MATCH(C9, 'Hub CPC 226'!B:B, 0)), "")} -> 12 | I9: {=IFERROR(INDEX('Hub Users 226'!A:A, MATCH(C9, 'Hub Users 226'!B:B, 0)), "")} -> 32 | K9: 5/16/22 SB emailed for re-engagement 12/30/21 SB sent IR2 FY21-22 schedule list for matching 12/10/21 and 12/13/21 SB reached-out via text to match for FY21-22 IR1, Ashley unable due to health concerns. Reach out for IR2 to see if she can | L9: 43484.717 | Q9: 4526 Kensington Dr. San Diego, CA 92116 | R9: San Diego, CA | S9: San Diego | T9: CA | U9: ELM Learning | AB9: =IFERROR(__xludf.DUMMYFUNCTION("IF( ISNUMBER(MATCH( C9, IMPORTRANGE(""https://docs.google.com/spreadsheets/d/1yTh1ELC33JHYOeEdgIiEclxPRyh0zOKtlawDltfUay8"",""'Champions'!A:A""), 0 )), ""Outreach Conducted"", """")"),"")
A10: Anne | B10: Tam | C10: =CONCATENATE(A10," ",B10) -> Anne Tam | D10: 347-528-1314 | E10: agwtam@gmail.com | F10: Active CPC | G10: 112 | H10: {=IFERROR(INDEX('Hub CPC 226'!A:A, MATCH(C10, 'Hub CPC 226'!B:B, 0)), "")} -> 13 | I10: {=IFERROR(INDEX('Hub Users 226'!A:A, MATCH(C10, 'Hub Users 226'!B:B, 0)), "")} -> 33 | K10: 3/17/23 Confirmed group for IR3 3/14/23 agreed to Wheels schedule, emailing About Interns 3/8/23 SB emailed about IR3 2/8/23 unavailable for IR2 - starting new job. SB emailed asking for updated job information 2/6/23 CT asked for IR2 with Wheels schedule 10/14/22 Anne confirmed wheels availability 10/13/22 SB sent match request for Wheels 7/11/22 Anne unavailable for IRS SB 7/7/22 LG called, emailed for IRS availability 3/21/22 Not available for IR3 CT 1/7/22 Update job info and added new resume SB 01/05/22 CT sent follow up email for matching 12/30/21 SB sent IR2 FY21-22 schedule list for matching JPS sent re-engagement email to Anne on 1/6/2021 | L10: 43484.724 | M10: 7 | N10: 12 | O10: 37 | P10: 26 | Q10: 4705 47th Ave #1F Woodside, NY 11377 | S10: Woodside | T10: NY | U10: CUREBASE | V10: FY 22 - 23, FY 21 - 22 | W10: Skirlie De La Cruz, Ayele Dounou, Ismatu Barry, Fatoumata Barry, Zhihao Huang, Yechi Ma, JiaJing Li, Lhianna Capell, Rashel Cabreja, Ashley Diaz, Karina Tejada, Schayna Ceballos, Kimberly Paulino, Anais Martinez and Aaliyah Escalante | X10: ICHSBronx, WheelsNYC, FlushingIHS | AB10: =IFERROR(__xludf.DUMMYFUNCTION("IF( ISNUMBER(MATCH( C10, IMPORTRANGE(""https://docs.google.com/spreadsheets/d/1yTh1ELC33JHYOeEdgIiEclxPRyh0zOKtlawDltfUay8"",""'Champions'!A:A""), 0 )), ""Outreach Conducted"", """")"),"")
A11: Afia | B11: Howladar | C11: =CONCATENATE(A11," ",B11) -> Afia Howladar | D11: 13475250223 | E11: ahowladar98@gmail.com | F11: Inactive CPC | G11: 663 | H11: {=IFERROR(INDEX('Hub CPC 226'!A:A, MATCH(C11, 'Hub CPC 226'!B:B, 0)), "")} -> 14 | I11: {=IFERROR(INDEX('Hub Users 226'!A:A, MATCH(C11, 'Hub Users 226'!B:B, 0)), "")} -> 34 | J11: Health Sciences/Medicine | K11: 10/26/22 Afia emailed, &#34;Hope you have been well! I am reaching out to be pulled from the SpeakHire program as I am currently interviewing at other companies and likely will not be with my current company very long. I apologize for pulling out last second and I wish you luck!&#34; SB followed up to see if we could reach out once she has settled at her new job - marking as inactive for now 9/26/22 Afia signed up for 10/27 training and said about match, &#34;need to conduct these sessions during my lunch, I would need them to take place anytime between 11am-3pm.&#34; need to see if any group can meet at that time. SB 9/24/22 SB followed up for training and asked for IR1 for Ellis 9/21/22 She is interested in IR1 but January is busy so may need to reschedule those sessions early. SB Passed screening- sending training email. 9/21/22 SB 9/14/22 SB sent screening scheduling follow up 9/9/22 SB sent screening scheduling email | L11: 44812.976 | M11: 12 | N11: 28 | O11: 76 | P11: 5 | Q11: 526 east 85th st #4D | R11: New York, NY | S11: New York | T11: NY | U11: Russell Tobin | AB11: =IFERROR(__xludf.DUMMYFUNCTION("IF( ISNUMBER(MATCH( C11, IMPORTRANGE(""https://docs.google.com/spreadsheets/d/1yTh1ELC33JHYOeEdgIiEclxPRyh0zOKtlawDltfUay8"",""'Champions'!A:A""), 0 )), ""Outreach Conducted"", """")"),"")
A12: Amy | B12: Meredith Jones | C12: =CONCATENATE(A12," ",B12) -> Amy Meredith Jones | D12: 310-666-0661 | E12: aj@recollectbetter.com | F12: Inactive CPC | G12: 63 | H12: {=IFERROR(INDEX('Hub CPC 226'!A:A, MATCH(C12, 'Hub CPC 226'!B:B, 0)), "")} -> 15 | I12: {=IFERROR(INDEX('Hub Users 226'!A:A, MATCH(C12, 'Hub Users 226'!B:B, 0)), "")} -> 35 | J12: Health Sciences/Medicine | K12: Amy responded 5/17/22 &#34; Unfortunately im still grappling with chronic illness and not able to support in this way. Thank you. &#34; 5/16/22 SB sent re-engagement email 12/30/21 SB sent IR2 FY21-22 schedule list for matching email 8/10/21 responded they currently can't be in the program due to health reasons but will still like to stay in contact. HH JPS followed up via email once again on 7/22/21 and let Amy know that it appears she did go through screening - gaging her interested to move forward in this process. HH voicemail/text 7/20/21 JPS sent an outreach email on 6/2/21 Amy was screened by Scotney on 9/7/2018. She was unable to complete the training process due to an illness in September 2018. | L12: 43338.743 | Q12: 28295 Via Rueda San Juan Capistrano, CA 92675 | S12: San Juan Capistrano | T12: CA | U12: Love Saves Lives, Inc. | AB12: =IFERROR(__xludf.DUMMYFUNCTION("IF( ISNUMBER(MATCH( C12, IMPORTRANGE(""https://docs.google.com/spreadsheets/d/1yTh1ELC33JHYOeEdgIiEclxPRyh0zOKtlawDltfUay8"",""'Champions'!A:A""), 0 )), ""Outreach Conducted"", """")"),"")
A13: Alyssa Jean | B13: Marion Daum | C13: =CONCATENATE(A13," ",B13) -> Alyssa Jean Marion Daum | D13: 949-266-7357 | E13: ajmdaum@gmail.com | F13: Inactive CPC | G13: 208 | H13: {=IFERROR(INDEX('Hub CPC 226'!A:A, MATCH(C13, 'Hub CPC 226'!B:B, 0)), "")} -> 16 | I13: {=IFERROR(INDEX('Hub Users 226'!A:A, MATCH(C13, 'Hub Users 226'!B:B, 0)), "")} -> 36 | K13: 12/27/21 Unable do IR2, &#34;For the foreseeable future, I will not be able to do any mentoring&#34; SB 12/22/21 SB sent IR2 FY21-22 schedule list for matching Alyssa responded to outreach on 2/10/21 and said, &#34;Thank you for reaching out. Unfortunately, I will be unable to take on matches this school year, but I would love to reconnect next school year. Also, will you please update my email to ajmdaum@gmail.com ? This is my work email, I would prefer to be reached via my personal email.&#34; JPS emailed on 2/10/21 to see if Alyssa can accommodate an IR2 20-21 match | L13: 43727.731 | Q13: 46 Camino del Oro RSM, CA 92688 | R13: Foothill Ranch, CA | S13: Foothill Ranch | T13: CA | U13: ExoAnalytic Solutions | AB13: =IFERROR(__xludf.DUMMYFUNCTION("IF( ISNUMBER(MATCH( C13, IMPORTRANGE(""https://docs.google.com/spreadsheets/d/1yTh1ELC33JHYOeEdgIiEclxPRyh0zOKtlawDltfUay8"",""'Champions'!A:A""), 0 )), ""Outreach Conducted"", """")"),"")
A14: Akanksha | B14: Raina | C14: =CONCATENATE(A14," ",B14) -> Akanksha Raina | D14: 857-389-9018 | E14: akanksharaina@gmail.com | F14: Active CPC | G14: 387 | H14: {=IFERROR(INDEX('Hub CPC 226'!A:A, MATCH(C14, 'Hub CPC 226'!B:B, 0)), "")} -> 17 | I14: {=IFERROR(INDEX('Hub Users 226'!A:A, MATCH(C14, 'Hub Users 226'!B:B, 0)), "")} -> 37 | J14: Business | K14: 2/28/23 CT left voicemail &amp; sent text to about taking over Wheels group for IR2 2/27/23 CT sent email asking to take over Wheels group for IR2 12/14/21 SB called and she is unable due to traveling these months, asked to be reached out to for IR2 FY21-22 12/13/21 SB and CT reached out for IR1 FY21-22 match Akanksha atteneded a CPC Training on 4/10/21 with JPS Doubled Checked 1/19 (KW) | L14: 44200.643 | M14: 12 | N14: 47 | O14: 67 | P14: 3 | Q14: 888 8th Avenue, 12 O, NY | R14: New York | S14: New York | T14: NY | U14: Common Living | V14: FY 20 - 21 | W14: Trisha Landolt and Nicole Molano | X14: ClaremontIHS | AB14: =IFERROR(__xludf.DUMMYFUNCTION("IF( ISNUMBER(MATCH( C14, IMPORTRANGE(""https://docs.google.com/spreadsheets/d/1yTh1ELC33JHYOeEdgIiEclxPRyh0zOKtlawDltfUay8"",""'Champions'!A:A""), 0 )), ""Outreach Conducted"", """")"),"")
A15: Joseph | B15: Temowo | C15: =CONCATENATE(A15," ",B15) -> Joseph Temowo | D15: 9173016742 | E15: akintemowo@yahoo.com | F15: Inactive CPC | G15: 405 | H15: {=IFERROR(INDEX('Hub CPC 226'!A:A, MATCH(C15, 'Hub CPC 226'!B:B, 0)), "")} -> 18 | I15: {=IFERROR(INDEX('Hub Users 226'!A:A, MATCH(C15, 'Hub Users 226'!B:B, 0)), "")} -> 38 | J15: Armed Services/Law Enforcement | K15: 7/24/23 WW called - too busy for any round for the rest of the year, SB marking inactive re-engage summer of 24 12/13/22 SB sent follow up email about IR2 12/8/22 SB emailed for Ellis match 6/15/22 FY 21-22 IR3 he had low engagement from Interns and felt discouraged. Give him a break for IRS and give him stronger students next round. 4/14/22 Not available for IR3, lot of travelling internationally. CT Joseph is an active duty military member Joseph attended a training session on 3/8/21 with JPS Joseph was screened on 2/15/21 by Malak Baker. JPS sent follow up email &#43; invited Joseph to schedule a training JPS emailed on 2/7/2021 to schedule a Screening Call Double checked 1/26 (KW) | L15: 44200.769 | Q15: 14 Glacier Dr., Morris Plains | R15: New Jersey, United States | S15: Morris Plains | T15: NJ | U15: Bloom Energy Corporation | V15: FY 22 - 23, FY 21 - 22, FY 20 - 21 | W15: Rasheed Abdulla, Yasmin Abdulla, Awa Ndiaye, Naim Bakere, Marwin Silverio Rodriguez, Fatou Diedhiou, Carlos Ramirez, Cesar Misael Orellana Riera, Nasif Zaman, Yemili Goodridge, Munir Ahmad Bakhtyar, bessirou doukoure and dalissa cabrera | X15: ELLIS, FlushingIHS | AB15: =IFERROR(__xludf.DUMMYFUNCTION("IF( ISNUMBER(MATCH( C15, IMPORTRANGE(""https://docs.google.com/spreadsheets/d/1yTh1ELC33JHYOeEdgIiEclxPRyh0zOKtlawDltfUay8"",""'Champions'!A:A""), 0 )), ""Outreach Conducted"", """")"),"")
A16: Alina | B16: Ispas Montbriand | C16: =CONCATENATE(A16," ",B16) -> Alina Ispas Montbriand | D16: 267-235-7033 | E16: alina.ispas.09@gmail.com | F16: Active CPC | G16: 131 | H16: {=IFERROR(INDEX('Hub CPC 226'!A:A, MATCH(C16, 'Hub CPC 226'!B:B, 0)), "")} -> 19 | I16: {=IFERROR(INDEX('Hub Users 226'!A:A, MATCH(C16, 'Hub Users 226'!B:B, 0)), "")} -> 39 | K16: 7/15/23 SB emailed for IRS 2/21/23 CT sent email about being Seminar Speaker for IHS US 1/24/23 CT Alina was impacted by recent Google layoffs. Don't reach out to her until the end of Feb at the earliest. 10/4/22 SB emailed Alina for Ellis match, she confirmed availability 8/12/22 Interested in IR1 SB 4/8/22 passed training with SB 3/1/22 SB call Alina - leave VM and send text about training and Claremont Match 01/21/22 CT Screening Call passed, sent Orientation &amp; Onboarding email with session schedules IR2 12/28/21 SB sent IR2 FY21-22 schedule list for matching JPS sent an email via Champions@speakhire.org to schedule a training webinar on 7/21/21. Had a Screening Call with Scotney Jan 2019 - passed | L16: 43590.632 | Q16: 1824 Spruce Street, Apt 4F, Philadelphia, PA 19103 | S16: Philadelphia | T16: PA | U16: Google Workspace | V16: Seminars 23, FY 21 - 22, FY 22 - 23 | W16: Wladimir Veloz Balbuena, Mohamed Danso, Mariama Diallo, Jariel Fernandez and Johalyn Perez | X16: IHSUnionSquare, ELLIS, WheelsNYC | AB16: =IFERROR(__xludf.DUMMYFUNCTION("IF( ISNUMBER(MATCH( C16, IMPORTRANGE(""https://docs.google.com/spreadsheets/d/1yTh1ELC33JHYOeEdgIiEclxPRyh0zOKtlawDltfUay8"",""'Champions'!A:A""), 0 )), ""Outreach Conducted"", """")"),"")
A17: Alpa | B17: Lachhman Rajai | C17: =CONCATENATE(A17," ",B17) -> Alpa Lachhman Rajai | D17: 9175421226 | E17: alpa.rajai@gmail.com | F17: Active CPC | G17: 61 | H17: {=IFERROR(INDEX('Hub CPC 226'!A:A, MATCH(C17, 'Hub CPC 226'!B:B, 0)), "")} -> 20 | I17: {=IFERROR(INDEX('Hub Users 226'!A:A, MATCH(C17, 'Hub Users 226'!B:B, 0)), "")} -> 40 | J17: Entertainment/Lifestyle | K17: 7/18/23 WW emailed for IRS availability, FG called and left VM and texted 3/15/23 CT left voicemail &amp; sent text for IR3 3/14/23 CT left voicemail &amp; sent text about taking over group of Interns for IR2 01/05/22 CT sent follow up email for matching 12/30/21 SB sent IR2 FY21-22 schedule list for matching 12/20 SB called Alpa and left a Voicemail 12/17 SB sent Alpa a text about match for FY21-22 IR1 | L17: 43338.743 | Q17: 700 Grove St, Apt 5R, Jersey City, NJ 07310 | S17: Jersey City | T17: NJ | U17: Barclays | V17: FY 19 - 20 | W17: Nicole Quiga and Sabrin Haque | X17: FlushingHigh | AB17: =IFERROR(__xludf.DUMMYFUNCTION("IF( ISNUMBER(MATCH( C17, IMPORTRANGE(""https://docs.google.com/spreadsheets/d/1yTh1ELC33JHYOeEdgIiEclxPRyh0zOKtlawDltfUay8"",""'Champions'!A:A""), 0 )), ""Outreach Conducted"", """")"),"")
A18: Alvaro | B18: Pavas-Hincapie | C18: =CONCATENATE(A18," ",B18) -> Alvaro Pavas-Hincapie | D18: 19294367119 | E18: alpavash@gmail.com | F18: Prospective | G18: 539 | H18: {=IFERROR(INDEX('Hub CPC 226'!A:A, MATCH(C18, 'Hub CPC 226'!B:B, 0)), "")} -> 21 | I18: {=IFERROR(INDEX('Hub Users 226'!A:A, MATCH(C18, 'Hub Users 226'!B:B, 0)), "")} -> 41 | J18: Health Sciences/Medicine | K18: 4/3/23 CT sent follow up to schedule Screening Call 2/22/23 CT sent follow up email to re-engage 2/9/23 CT sent re-engagement email 5/24/22 SB sent re-engagement email Screening invite sent 11/7/21 | L18: 44505.633 | Q18: Calle 53C Sur #40B 78 Ap 904 | R18: Montreal, Quebec - Canadá | U18: Orbis International | AB18: =IFERROR(__xludf.DUMMYFUNCTION("IF( ISNUMBER(MATCH( C18, IMPORTRANGE(""https://docs.google.com/spreadsheets/d/1yTh1ELC33JHYOeEdgIiEclxPRyh0zOKtlawDltfUay8"",""'Champions'!A:A""), 0 )), ""Outreach Conducted"", """")"),"")
A19: Albert | B19: Rocco | C19: =CONCATENATE(A19," ",B19) -> Albert Rocco | D19: 2014017738 | E19: alrocco5@gmail.com | F19: Active CPC | G19: 359 | H19: {=IFERROR(INDEX('Hub CPC 226'!A:A, MATCH(C19, 'Hub CPC 226'!B:B, 0)), "")} -> 22 | I19: {=IFERROR(INDEX('Hub Users 226'!A:A, MATCH(C19, 'Hub Users 226'!B:B, 0)), "")} -> 42 | J19: Arts/Creative | K19: He texted WW 3/8/24: Please refrain from contacting me until 2025 7/11/23 emailed SB not available for IRS 7/10/23 SB emailed for IRS 12/26/22 responded saying he has many travel commitments and cannot participate in IR2. SB 12/22/22 SB emailed for Ellis match Albert attended a CPC Training Webinar on 1/16/2021 with JPS at 11 am est Hetal Jani had second screening call on November 17, 2020 -- he was able to understand our approach; seemed he looked more into what we did. Older, has a lot of experience, can guide a student with a lot of self-advocacy so they can ask targeted questions Jennifer Peterson-Sharma emailed Albert on 10/27/2020 to schedule a second screening call next week with Hetal Jani. Had a Mentor Screening Call on 10/13/2020 at 4:30 pm EST with Jennifer Peterson-Sharma. Albert is scheduled for a Screening Call on 10/13/2020. Albert was emailed on 10/12/2020 to schedule a mentor screening call | L19: 44116.51 | Q19: 131 Magnolia Ave, Tenafly, NJ | R19: NJ | S19: Tenafly | T19: NJ | U19: Koslow Scientific Company | V19: FY 21 - 22 | W19: Diego Dinardi, Lisvany Guzman, Kadidiatou Traore, Wendy Ouedraogo and Tariana Garcia Encarnacion | X19: ClaremontIHS, CrotonaIHS | AB19: =IFERROR(__xludf.DUMMYFUNCTION("IF( ISNUMBER(MATCH( C19, IMPORTRANGE(""https://docs.google.com/spreadsheets/d/1yTh1ELC33JHYOeEdgIiEclxPRyh0zOKtlawDltfUay8"",""'Champions'!A:A""), 0 )), ""Outreach Conducted"", """")"),"")
A20: Amanda | B20: Morgan Mackler | C20: =CONCATENATE(A20," ",B20) -> Amanda Morgan Mackler | D20: 2015464923 | E20: amackler40@gmail.com | F20: Active CPC | G20: 361 | H20: {=IFERROR(INDEX('Hub CPC 226'!A:A, MATCH(C20, 'Hub CPC 226'!B:B, 0)), "")} -> 23 | I20: {=IFERROR(INDEX('Hub Users 226'!A:A, MATCH(C20, 'Hub Users 226'!B:B, 0)), "")} -> 43 | J20: Service/Hospitality Industry | K20: 12/20 SB called Amanda and left a Voicemail 12/17 SB sent Amanda a text about match for FY21-22 IR1 Amanda attended a training on 2/26/21 with JPS JPS followed up on 2/17/21 to schedule Amanda for a training JPS sent Amanda congratulations email &#43; tried to get Amanda to schedule a training in January, but Amanda was unable to attend. JPS followed up on 2/4/21 to see if Amanda wanted to attend a training in February. Amanda was screened on 10/22/2020 at 4:20 pm EST by Jennifer Peterson-Sharma. Jennifer Peterson-Sharma emailed to schedule a screening call on 10/22/2020. | L20: 44119.568 | Q20: New York | T20: NY | U20: KPMG | V20: FY 20 - 21 | W20: Bradley Edwards and Bindadevi Sukhandan | X20: QueensPrepAcad | AB20: =IFERROR(__xludf.DUMMYFUNCTION("IF( ISNUMBER(MATCH( C20, IMPORTRANGE(""https://docs.google.com/spreadsheets/d/1yTh1ELC33JHYOeEdgIiEclxPRyh0zOKtlawDltfUay8"",""'Champions'!A:A""), 0 )), ""Outreach Conducted"", """")"),"")
A21: Andrea | B21: Goodfriend | C21: =CONCATENATE(A21," ",B21) -> Andrea Goodfriend | D21: 18184513081 | E21: amandel@pinterest.com | F21: Active CPC | G21: 506 | H21: {=IFERROR(INDEX('Hub CPC 226'!A:A, MATCH(C21, 'Hub CPC 226'!B:B, 0)), "")} -> 24 | I21: {=IFERROR(INDEX('Hub Users 226'!A:A, MATCH(C21, 'Hub Users 226'!B:B, 0)), "")} -> 44 | J21: Education | K21: 5/10/23 email auto responded - on maternity leave 2/7/23 CT left voicemail &amp; sent text to check in 1/11/23 CT sent follow up email 01/03/23 CT sent follow up email 12/22/22 CT sent check in email 12/22/21 SB sent IR2 FY21-22 schedule list for matching Had to back out after match and a few sessions due to family emergency 12/7/21 SB Completed training 11/12/21 SB 10/26/21 SB Screening note: She prefers to be matched with Interns who identify as being from Central or South America. 10/27/21 SB sent congrats and training scheduling email. Andrea responded asking for more dates, SB asked her availability second week of November Passed screening on 10/26/21 SB Sent screening scheduling email on10/8/21 SB | L21: 44476.76 | Q21: 5130 INADALE AVE, Los Angeles, CA 90043 | R21: Los Angeles, CA | S21: Los Angelos | T21: CA | U21: Pinterest | AB21: =IFERROR(__xludf.DUMMYFUNCTION("IF( ISNUMBER(MATCH( C21, IMPORTRANGE(""https://docs.google.com/spreadsheets/d/1yTh1ELC33JHYOeEdgIiEclxPRyh0zOKtlawDltfUay8"",""'Champions'!A:A""), 0 )), ""Outreach Conducted"", """")"),"")
A22: Alissa | B22: Meddlesaint | C22: =CONCATENATE(A22," ",B22) -> Alissa Meddlesaint | D22: 484-903-2662 | E22: ameddlesaint@gmail.com | F22: Prospective | G22: 132 | H22: {=IFERROR(INDEX('Hub CPC 226'!A:A, MATCH(C22, 'Hub CPC 226'!B:B, 0)), "")} -> 25 | I22: {=IFERROR(INDEX('Hub Users 226'!A:A, MATCH(C22, 'Hub Users 226'!B:B, 0)), "")} -> 45 | J22: STEM (Science, Technology, Engineering, Math) | K22: 8/18/23 - AT sent re-engagement message on LinkedIn. Awaiting response. 8/8/23 - AT emailed and sent re-engagement txt. Awaiting response. 4/3/23 CT sent follow up to schedule Screening Call 2/22/23 CT sent follow email to re-engage 2/9/23 CT sent re-engagement email 12/13/22 CT sent re-engagement email 5/24/22 SB sent re-engagement email 11/15/21 SB sent re-engagement email Alissa scheduled a screening call on 7/29/21 but did not show up. JPS gave her a call &amp; she said she did not realize it was on Google Meet and will schedule for another time. HH called is really interested in getting into the program would like a follow up email 7/20/21 JPS sent outreach email from Champions@speakhire.org on 7/20/21 uploaded to Kintone but marked as inactive/yellow until screening complete | L22: 43590.632 | Q22: 318 W Wilkes Barre St | R22: Easton | S22: Easton | T22: PA | U22: MAC Cosmetics | AB22: =IFERROR(__xludf.DUMMYFUNCTION("IF( ISNUMBER(MATCH( C22, IMPORTRANGE(""https://docs.google.com/spreadsheets/d/1yTh1ELC33JHYOeEdgIiEclxPRyh0zOKtlawDltfUay8"",""'Champions'!A:A""), 0 )), ""Outreach Conducted"", """")"),"")
A23: Amelia | B23: Geary | C23: =CONCATENATE(A23," ",B23) -> Amelia Geary | D23: 3472478763 | E23: ameliachamberlain@yahoo.com | F23: Inactive CPC | G23: 327 | H23: {=IFERROR(INDEX('Hub CPC 226'!A:A, MATCH(C23, 'Hub CPC 226'!B:B, 0)), "")} -> 26 | I23: {=IFERROR(INDEX('Hub Users 226'!A:A, MATCH(C23, 'Hub Users 226'!B:B, 0)), "")} -> 46 | K23: 9/30/22 Amelia emailed saying &#34;For the foreseeable future, I have very limited availability. Unfortunately, I think it best to remove me as a potential mentor for now. I?m happy to reach out in the future when things become more manageable.&#34; SB responded offering to reach out for future rounds 9/28/22 SB emailed for ellis match 7/5/22 LG called, texted for IRS availability; Amelia is never available for Summer, wants to be contacted for IR1 1/8/22 SB updated location from Lima, Peru to Barbados 12/22/21 SB sent IR2 FY21-22 schedule list for matching Unavailable for IR1 21 due to health, check for IR2 SB Amelia was trained on 10/20/2020 at 5:15 pm EST with Jennifer Peterson-Sharma Jennifer Peterson-Sharma called Amelia on 10/6/2020. She affirmed that she is available to mentor for the Round One mentoring session. She signed up for October 20 Training Webinar. Amelia was screened on 9/17/2020 by Kiesha Charles Emailed her to schedule a screening call on september 17th 2020 at 7pm Emailed on 8/31/2020 about setting up screening call | L23: 43989.603 | Q23: 85 Columbia Street, Apartment 2E | R23: Barbados | U23: Orbis International | V23: Seminars 22, Seminars 21, FY 20 - 21, FY 21 - 22 | W23: Francheska Caraballo, Aaliyah Aybar, Avril Mejia, Genesis Lochart, Ivania Posada, Licsy Reyes, Asmaa Alkhadashi, Arwa Alhaj, Yann Noumbi and Shabiha Rahman | X23: P2GManhattan, CypressHills, IHSUnionSquare, CrotonaIHS, ELLIS | AB23: =IFERROR(__xludf.DUMMYFUNCTION("IF( ISNUMBER(MATCH( C23, IMPORTRANGE(""https://docs.google.com/spreadsheets/d/1yTh1ELC33JHYOeEdgIiEclxPRyh0zOKtlawDltfUay8"",""'Champions'!A:A""), 0 )), ""Outreach Conducted"", """")"),"") | AD23: Issue 11 | AE23: 44593 | AF23: Thank you for your support letter | AG23: 50
A24: Ahmed | B24: Imam | C24: =CONCATENATE(A24," ",B24) -> Ahmed Imam | D24: 16027368545 | E24: ami2136@columbia.edu | F24: Active CPC | G24: 592 | H24: {=IFERROR(INDEX('Hub CPC 226'!A:A, MATCH(C24, 'Hub CPC 226'!B:B, 0)), "")} -> 27 | I24: {=IFERROR(INDEX('Hub Users 226'!A:A, MATCH(C24, 'Hub Users 226'!B:B, 0)), "")} -> 47 | J24: Business | K24: 12/29/23 SB reached out just to check in and touch base - hoping to re-engage 3/22/23 SB sent text for IR3 3/17/23 SB sent follow up email about IR3 3/14/23 SB emailed for IR3 wheels 12/20/22 SB followed up via email for IR2 match 12/16/22 SB emailed for IR2 queens match 10/04/22 Not available for IR1. CT 7/9/22 SB contacted for IRS match 4/27/22 Not available for Seminars in May. CT Completed Onboarding and Orientation Webinar 1/28/22 SB 01/18/22 CT sent email with training dates, handbook, instructional guide 1/17/22 SB sent screening follow up Sent screening scheduling email 1/13/22 SB | L24: 44571.864 | M24: 12 | N24: 28 | O24: 75 | P24: 3 | Q24: 230 W. 55th St #7D, New York, NY 10019 | R24: New York City | S24: New York | T24: NY | U24: Kirkland & Ellis LLP | V24: FY 21 - 22 | W24: Kenia Cholom, Afrin Tripti, Yiengchuk Dorji and Yonathan Martinez | X24: IHS Health | AB24: =IFERROR(__xludf.DUMMYFUNCTION("IF( ISNUMBER(MATCH( C24, IMPORTRANGE(""https://docs.google.com/spreadsheets/d/1yTh1ELC33JHYOeEdgIiEclxPRyh0zOKtlawDltfUay8"",""'Champions'!A:A""), 0 )), ""Outreach Conducted"", """")"),"")
A25: Abigail | B25: Mawhirter | C25: =CONCATENATE(A25," ",B25) -> Abigail Mawhirter | D25: 12547233110 | E25: amm09b@acu.edu | F25: Active CPC | G25: 445 | H25: {=IFERROR(INDEX('Hub CPC 226'!A:A, MATCH(C25, 'Hub CPC 226'!B:B, 0)), "")} -> 28 | I25: {=IFERROR(INDEX('Hub Users 226'!A:A, MATCH(C25, 'Hub Users 226'!B:B, 0)), "")} -> 48 | K25: 1/9/24 agreed to IR2, but had to drop due to health issues SB 10/5/23 Abigail expressed interests, will keep in touch about health science groups 9/18/23 WW emailed for IR1 Abigail made the #ChampionItForward video 7/24/23 Abigail reached out expressing interest in IRS, SB said we would follow up for IR1 3/30/23 texted SB, not available for IR3 but interested in IRS 3/27/23 SB sent dates of sessions - Abigail said mondays should work, checking schedule 3/21/23 SB sent text about IR3 availability - messaged back saying she would check work schedule 9/22/22 Abigail will not know her schedule until late October. She said, &#34; I do typically try to be off on Thursdays, since I tend to have other meetings at least 3 of the 4 Thursdays out of a month. Is that helpful? If not, I can still try to accommodate for the proposed Monday group?&#34; - will possibly work for Wheels. Will follow up as round gets closer and we get Wheels applications in. SB 9/20/22 match request sent to Abigail SB PQT confirmed by text on 8/4/22 for IR1 Ask her before giving her more than 3 Interns. Given Abigail's hectic working schedule at the hospital, she watched the onboarding video in replacement of attending a webinar. Abigail was screened by SU on 3/23/21 Abigail responded 2/12/21 saying she was very interested in being matched but needs a heads up on the schedule because her working hours vary every week. JPS sent her the schedules to potentially match for IR3 20-21. JPS followed up on 2/10/21 email to see if abigail could be a champion for the IR2 20-21 session JPS emailed on 2/10/2021 to schedule a screening call | L25: 44236.933 | Q25: 425 Sharron Dr, Woodway, TX 76712 | R25: Waco, TX | S25: Waco | T25: TX | U25: BSWH Hillcrest Baptist Medical Center | V25: FY 22 - 23, FY 21 - 22, FY 20 - 21 | W25: Schayna Ceballos, Tryana Hernandez, Adalbelys Polanco, Daylan Peralta, Amizo Kante, Naimatou Sefou Moussa, Lady Villa, Ilse Cotiy Tambriz, Rafialy Carrasco, Oceanne Compaore, Liccy Dubon Zamora, Raimelis Garcia, Batma Ramazanova and Zuura Ramazanova | X25: WheelsNYC, ELLIS, IHSUnionSquare, ClaremontIHS, CrotonaIHS, GWHS | AB25: =IFERROR(__xludf.DUMMYFUNCTION("IF( ISNUMBER(MATCH( C25, IMPORTRANGE(""https://docs.google.com/spreadsheets/d/1yTh1ELC33JHYOeEdgIiEclxPRyh0zOKtlawDltfUay8"",""'Champions'!A:A""), 0 )), ""Outreach Conducted"", """")"),"")
A26: Amrita | B26: Pritam | C26: =CONCATENATE(A26," ",B26) -> Amrita Pritam | D26: 4159965440 | E26: amritap4@gmail.com | F26: Active CPC | G26: 54 | H26: {=IFERROR(INDEX('Hub CPC 226'!A:A, MATCH(C26, 'Hub CPC 226'!B:B, 0)), "")} -> 29 | I26: {=IFERROR(INDEX('Hub Users 226'!A:A, MATCH(C26, 'Hub Users 226'!B:B, 0)), "")} -> 49 | J26: Law | K26: 7/18/23 WW emailed for IRS - responded not available, on maternity leave 4/26/23 SB emailed for IR2 1/13/23 SB emailed for IR2 - agreed to Monday schedule 10/05/22 Not available for IR1. Will be in India in November &amp; December but interested in Seminars. Sent her some Seminar schedules. CT 2/3/22 HJ texted her -- she had a new baby (Aayansh) and won't be available until maybe 22-23 IR1 01/05/22 CT sent follow up email for matching 12/30/21 SB sent IR2 FY21-22 schedule list for matching Amrita emailed on 1/8/2021 informing Jennifer Peterson-Sharma that she will not be available for matching until June 2021, although she would still love to be a part of the program. Norrell spoke with 05/18/2020 We need updated resume for Amrita. Her new title is: Microsoft, Software Develop Engineer, Domain is Android. Hetal called and left a voice message on 3/26/2020 | L26: 43338.743 | Q26: amritap4@gmail.com | S26: San Francisco | T26: CA | U26: Microsoft | V26: FY 22 - 23 | W26: Yancen Rodriguez and Kenry Aldana | X26: CrotonaIHS | AB26: =IFERROR(__xludf.DUMMYFUNCTION("IF( ISNUMBER(MATCH( C26, IMPORTRANGE(""https://docs.google.com/spreadsheets/d/1yTh1ELC33JHYOeEdgIiEclxPRyh0zOKtlawDltfUay8"",""'Champions'!A:A""), 0 )), ""Outreach Conducted"", """")"),"")
A27: Amy | B27: Sit | C27: =CONCATENATE(A27," ",B27) -> Amy Sit | D27: 510-501-9776 | E27: amy_sit@alumni.brown.edu | F27: Active CPC | G27: 202 | H27: {=IFERROR(INDEX('Hub CPC 226'!A:A, MATCH(C27, 'Hub CPC 226'!B:B, 0)), "")} -> 30 | I27: {=IFERROR(INDEX('Hub Users 226'!A:A, MATCH(C27, 'Hub Users 226'!B:B, 0)), "")} -> 50 | K27: Amy made the #ChampionItForward video 7/18/23 WW emailed for IRS, PQ followed up with text and call - not available for IRS, asked for IR1 3/29/23 SB sent text for IR3 11/28/22 Unavailable for IR2 - traveling in Feb. SB 10/31/22 Amy emailed SB saying, &#34; I just received word about a new workshop schedule for the next 8 weeks, I won't be available on Thursdays after all.&#34; 10/14/22 SB emailed for Wheels availability - Amy confirmed availability 1/10/22 SB sent follow up email 1/5/22 SB sent IR2 FY21-22 schedule list for matching JPS emailed on 1/5/2021 to check her engagement status. Amy responded on 1/13/2021 saying: &#34;Happy New Year! Apologies for the delay in response. In response to your questions, 1) I am still interested in being a Champion for the upcoming round, 2) I don't have a need for a refresh training at this time.&#34; Amy called Hetal back on March 24th saying she'd love to mentor during this time of COVID-19 and would love to share within her company -- knows women who would be interested Hetal called on March 19, 2020 and left a voice message to reengage. | L27: 43683.442 | M27: 9 | N27: 20 | O27: 43 | P27: 41 | Q27: 1081 Eastern Parkway Brooklyn NY 11213" | R27: NYC | S27: Brooklyn | T27: NY | U27: Capgemini Invent | V27: EY 19 - 20, FY 21 - 22, FY 20 - 21 | W27: Dema Alhuraibi, Karidjatou Kone, Fatou Diedhiou, Naim Bakere, Mingyu (Carl) Huo and Yongqiang Tan | X27: Abraham Lincoln HS, ELLIS, FlushingIHS | AB27: =IFERROR(__xludf.DUMMYFUNCTION("IF( ISNUMBER(MATCH( C27, IMPORTRANGE(""https://docs.google.com/spreadsheets/d/1yTh1ELC33JHYOeEdgIiEclxPRyh0zOKtlawDltfUay8"",""'Champions'!A:A""), 0 )), ""Outreach Conducted"", """")"),"")
A28: Amy | B28: Patel | C28: =CONCATENATE(A28," ",B28) -> Amy Patel | D28: 312-848-6508 | E28: amyp55@gmail.com | F28: Inactive CPC | G28: 45 | H28: {=IFERROR(INDEX('Hub CPC 226'!A:A, MATCH(C28, 'Hub CPC 226'!B:B, 0)), "")} -> 31 | I28: {=IFERROR(INDEX('Hub Users 226'!A:A, MATCH(C28, 'Hub Users 226'!B:B, 0)), "")} -> 51 | J28: Health Sciences/Medicine | K28: 11/28/22 unsubscribed from newsletter SB 10/18/22 CT marked as abandoned (see notes below) 5/24/22 SB sent re-engagement email 1/5/22 Unsubscribed from newsletter SB Amy responded to outreach on 5/27/21 and said: &#34;I don't have the bandwidth for this right now and do not want to commit to something I can't follow through on. I will reach out once things settle down.&#34; JPS called on 5/26/21. Amy was running into a meeting and couldn't talk, so JPS sent email. | L28: 43338.743 | Q28: 73 East Lake St, Chicago, IL 60601 | S28: Chicago | T28: IL | U28: BASF | AB28: =IFERROR(__xludf.DUMMYFUNCTION("IF( ISNUMBER(MATCH( C28, IMPORTRANGE(""https://docs.google.com/spreadsheets/d/1yTh1ELC33JHYOeEdgIiEclxPRyh0zOKtlawDltfUay8"",""'Champions'!A:A""), 0 )), ""Outreach Conducted"", """")"),"")
A29: Anya | B29: Smith | C29: =CONCATENATE(A29," ",B29) -> Anya Smith | D29: 16507850781 | E29: anakrokhina@hotmail.com | F29: Active CPC | G29: 668 | H29: {=IFERROR(INDEX('Hub CPC 226'!A:A, MATCH(C29, 'Hub CPC 226'!B:B, 0)), "")} -> 32 | I29: {=IFERROR(INDEX('Hub Users 226'!A:A, MATCH(C29, 'Hub Users 226'!B:B, 0)), "")} -> 52 | J29: Health Sciences/Medicine | K29: 1/9/24 WW LinkedIn message for IR2 Ellis 4/24/23 SB messaged Anya for IR3 - responded, &#34;I have been having a bit of a hard time personally around managing stress related to the looming layoffs and also won't know my own job status until later next month. In light of that I would prefer to not take one more right now. I do hope to help out again soon&#34; 4/18/23 SB emailed for IR3 3/6/23 CT updated phone number from ?(425) 737-8230? to &#43;16507850781 2/23/23 CT left voicemail &amp; sent text asking for Seminar 2/22/23 CT sent email asking about being Seminar Speaker for IHS Union Square 1/10/23 CT not available for IR2 because of new role at work and finishing last semester of MS degree. Asked to check in for IR3. 3/31/22 Not available for internship rounds until 2023 due to maternity leave. CT Completed Onboarding and Training 8/14/21 SB Training scheduled for 8/14/21 on 7/26/21 by SB Screened and passed on 7/21/21 by SB Her email address is under &#34;Anna&#34; but she prefers to be called &#34;Anya&#34; SB sent a screening call email on 7/12/21 | L29: 44833.453 | Q29: 5641 402nd Ave Se | R29: Snoqualmie, WA | S29: Snoqualmie | T29: WA | U29: Meta (formerly Facebook) | V29: FY 21 - 22, Seminars 22 | W29: Rasel Ali and Akira Quezada | X29: ICHSBronx, ClaremontIHS | AB29: =IFERROR(__xludf.DUMMYFUNCTION("IF( ISNUMBER(MATCH( C29, IMPORTRANGE(""https://docs.google.com/spreadsheets/d/1yTh1ELC33JHYOeEdgIiEclxPRyh0zOKtlawDltfUay8"",""'Champions'!A:A""), 0 )), ""Outreach Conducted"", """")"),"")
A30: Anya | B30: Smith | C30: =CONCATENATE(A30," ",B30) -> Anya Smith | D30: 14257378230 | E30: anakrokhina@hotmail.com | F30: Active CPC | G30: 486 | H30: {=IFERROR(INDEX('Hub CPC 226'!A:A, MATCH(C30, 'Hub CPC 226'!B:B, 0)), "")} -> 32 | I30: {=IFERROR(INDEX('Hub Users 226'!A:A, MATCH(C30, 'Hub Users 226'!B:B, 0)), "")} -> 52 | J30: STEM (Science, Technology, Engineering, Math) | K30: 3/20/23 CT Anya has a lot going on with Meta layoffs and school. Reach out after August for FY or Seminars. 3/31/22 Not available for internship rounds until 2023 due to maternity leave. CT Completed Onboarding and Training 8/14/21 SB Training scheduled for 8/14/21 on 7/26/21 by SB Screened and passed on 7/21/21 by SB Her email address is under &#34;Anna&#34; but she prefers to be called &#34;Anya&#34; SB sent a screening call email on 7/12/21 | L30: 44387.781 | Q30: 5641 402nd Ave Se | R30: Snoqualmie, WA | S30: Snoqualmie | T30: WA | U30: Meta (formerly Facebook) | V30: Seminars 22, FY 21 - 22 | W30: Rasel Ali and Akira Quezada | X30: IHSUnionSquare, ICHSBronx | AB30: =IFERROR(__xludf.DUMMYFUNCTION("IF( ISNUMBER(MATCH( C30, IMPORTRANGE(""https://docs.google.com/spreadsheets/d/1yTh1ELC33JHYOeEdgIiEclxPRyh0zOKtlawDltfUay8"",""'Champions'!A:A""), 0 )), ""Outreach Conducted"", """")"),"")
A31: Anastasia | B31: Maria Savelyeva | C31: =CONCATENATE(A31," ",B31) -> Anastasia Maria Savelyeva | D31: 917-500-4224 | E31: anastasia.msavelyeva@gmail.com | F31: Inactive CPC | G31: 134 | H31: {=IFERROR(INDEX('Hub CPC 226'!A:A, MATCH(C31, 'Hub CPC 226'!B:B, 0)), "")} -> 33 | I31: {=IFERROR(INDEX('Hub Users 226'!A:A, MATCH(C31, 'Hub Users 226'!B:B, 0)), "")} -> 53 | J31: Service/Hospitality Industry | K31: 3/1/22 SB call, leave VM and send text to check status 1/24 SB call, VM, text 01/05/22 CT sent follow up email for matching 12/30/21 SB sent IR2 FY21-22 schedule list for matching Anastasia unreachable throughout IR1 FY 21-22 communications, marking as inactive 11/15/21 SB Hetal called and left a vm on 11/8/2021 asking if she's still interested. SB sent text with Intern round schedule 11/7/21 | L31: 43590.633 | P31: 29 | Q31: 6225 84th ST C60, Rego Park | R31: New York | S31: Middle Village | T31: NY | U31: The Smith | V31: FY 19 - 20 | W31: Mamdiara Ndiaye and Nassira Cisse | X31: ELLIS | AB31: =IFERROR(__xludf.DUMMYFUNCTION("IF( ISNUMBER(MATCH( C31, IMPORTRANGE(""https://docs.google.com/spreadsheets/d/1yTh1ELC33JHYOeEdgIiEclxPRyh0zOKtlawDltfUay8"",""'Champions'!A:A""), 0 )), ""Outreach Conducted"", """")"),"")
